<?xml version="1.0" ?>
<robot name="my_arm" xmlns:xacro="http://www.ros.org/wiki/xacro">
<xacro:include filename="$(find my_arm_description)/urdf/core/materials.xacro" />
<!-- ========== 虚拟基座 ========== -->
<link name="world"/>

<joint name="base_to_world" type="fixed">
  <parent link="world"/>
  <child link="base_link"/>
  <origin xyz="0 0 0.32" rpy="0 0 0"/>
</joint>
<!-- ================================== -->

<link name="base_link">
  <inertial>
    <origin xyz="0.0008464787530113904 -0.0002376902938994468 0.04677602289512804" rpy="0 0 0"/>
    <mass value="2.9601256922876837"/>
    <inertia ixx="0.011312" iyy="0.011909" izz="0.017539" ixy="-4e-05" iyz="-2.8e-05" ixz="7.4e-05"/>
  </inertial>
  <visual>
    <origin xyz="0 0 0" rpy="0 0 0"/>
    <geometry>
      <mesh filename="file:///home/lai/Desktop/ros2_ws/src/my_arm_description/meshes/base_link.stl" scale="0.001 0.001 0.001"/>
    </geometry>
    <material name="silver"/>
  </visual>
  <collision>
    <origin xyz="0 0 0" rpy="0 0 0"/>
    <geometry>
      <mesh filename="file:///home/lai/Desktop/ros2_ws/src/my_arm_description/meshes/base_link.stl" scale="0.001 0.001 0.001"/>
    </geometry>
  </collision>
</link>

<link name="arm_1_link_1">
  <inertial>
    <origin xyz="0.012623151298250049 -0.0003158130747682431 -0.07225102113341529" rpy="0 0 0"/>
    <mass value="0.48146371205984473"/>
    <inertia ixx="0.000245" iyy="0.000219" izz="0.000347" ixy="-0.0" iyz="1e-06" ixz="-1e-06"/>
  </inertial>
  <visual>
    <origin xyz="0.01251 0.0001 -0.17696" rpy="0 0 0"/>
    <geometry>
      <mesh filename="file:///home/lai/Desktop/ros2_ws/src/my_arm_description/meshes/arm_1_link_1.stl" scale="0.001 0.001 0.001"/>
    </geometry>
    <material name="silver"/>
  </visual>
  <collision>
    <origin xyz="0.01251 0.0001 -0.17696" rpy="0 0 0"/>
    <geometry>
      <mesh filename="file:///home/lai/Desktop/ros2_ws/src/my_arm_description/meshes/arm_1_link_1.stl" scale="0.001 0.001 0.001"/>
    </geometry>
  </collision>
</link>

<link name="servo_3_link_1">
  <inertial>
    <origin xyz="0.02239902764015798 -0.00012706497809415707 -2.1755726442584944e-08" rpy="0 0 0"/>
    <mass value="0.2843033821982282"/>
    <inertia ixx="4e-05" iyy="6.2e-05" izz="7.3e-05" ixy="1e-06" iyz="-0.0" ixz="0.0"/>
  </inertial>
  <visual>
    <origin xyz="0.0072 0.0008 -0.3086" rpy="0 0 0"/>
    <geometry>
      <mesh filename="file:///home/lai/Desktop/ros2_ws/src/my_arm_description/meshes/servo_3_link_1.stl" scale="0.001 0.001 0.001"/>
    </geometry>
    <material name="silver"/>
  </visual>
  <collision>
    <origin xyz="0.0072 0.0008 -0.3086" rpy="0 0 0"/>
    <geometry>
      <mesh filename="file:///home/lai/Desktop/ros2_ws/src/my_arm_description/meshes/servo_3_link_1.stl" scale="0.001 0.001 0.001"/>
    </geometry>
  </collision>
</link>

<link name="arm_3_link_1">
  <inertial>
    <origin xyz="0.09160800621927975 -0.018527194341208024 0.00017998424453308237" rpy="0 0 0"/>
    <mass value="0.8614146702314018"/>
    <inertia ixx="0.000403" iyy="0.00217" izz="0.002485" ixy="-8.3e-05" iyz="-0.0" ixz="-8e-06"/>
  </inertial>
  <visual>
    <origin xyz="-0.028 -0.0175 -0.3086" rpy="0 0 0"/>
    <geometry>
      <mesh filename="file:///home/lai/Desktop/ros2_ws/src/my_arm_description/meshes/arm_3_link_1.stl" scale="0.001 0.001 0.001"/>
    </geometry>
    <material name="silver"/>
  </visual>
  <collision>
    <origin xyz="-0.028 -0.0175 -0.3086" rpy="0 0 0"/>
    <geometry>
      <mesh filename="file:///home/lai/Desktop/ros2_ws/src/my_arm_description/meshes/arm_3_link_1.stl" scale="0.001 0.001 0.001"/>
    </geometry>
  </collision>
</link>

<link name="servo_4_link_1">
  <inertial>
    <origin xyz="0.33571890838818963 -0.17555726528762458 0.012433978227253617" rpy="0 0 0"/>
    <mass value="0.2843033821982282"/>
    <inertia ixx="6.2e-05" iyy="4e-05" izz="7.3e-05" ixy="1e-06" iyz="0.0" ixz="-0.0"/>
  </inertial>
  <visual>
    <origin xyz="0.1481 -0.186792 -0.296366" rpy="0 0 0"/>
    <geometry>
      <mesh filename="file:///home/lai/Desktop/ros2_ws/src/my_arm_description/meshes/servo_4_link_1.stl" scale="0.001 0.001 0.001"/>
    </geometry>
    <material name="silver"/>
  </visual>
  <collision>
    <origin xyz="0.1481 -0.186792 -0.296366" rpy="0 0 0"/>
    <geometry>
      <mesh filename="file:///home/lai/Desktop/ros2_ws/src/my_arm_description/meshes/servo_4_link_1.stl" scale="0.001 0.001 0.001"/>
    </geometry>
  </collision>
</link>

<link name="arm_4_link_1">
  <inertial>
    <origin xyz="0.01526866733342841 0.0001623881743855718 0.00357138406986951" rpy="0 0 0"/>
    <mass value="0.20631364283305076"/>
    <inertia ixx="7.2e-05" iyy="4.6e-05" izz="6.7e-05" ixy="-2e-06" iyz="0.0" ixz="-9e-06"/>
  </inertial>
  <visual>
    <origin xyz="-0.206192 0.001566 -0.3088" rpy="0 0 0"/>
    <geometry>
      <mesh filename="file:///home/lai/Desktop/ros2_ws/src/my_arm_description/meshes/arm_4_link_1.stl" scale="0.001 0.001 0.001"/>
    </geometry>
    <material name="silver"/>
  </visual>
  <collision>
    <origin xyz="-0.206192 0.001566 -0.3088" rpy="0 0 0"/>
    <geometry>
      <mesh filename="file:///home/lai/Desktop/ros2_ws/src/my_arm_description/meshes/arm_4_link_1.stl" scale="0.001 0.001 0.001"/>
    </geometry>
  </collision>
</link>

<link name="servo_5_link_1">
  <inertial>
    <origin xyz="0.40934087105025296 -0.3223849498003535 -0.03508338265137656" rpy="0 0 0"/>
    <mass value="0.2843033821982282"/>
    <inertia ixx="4e-05" iyy="6.2e-05" izz="7.3e-05" ixy="-1e-06" iyz="-0.0" ixz="-0.0"/>
  </inertial>
  <visual>
    <origin xyz="0.16135 -0.320395 -0.344695" rpy="0 0 0"/>
    <geometry>
      <mesh filename="file:///home/lai/Desktop/ros2_ws/src/my_arm_description/meshes/servo_5_link_1.stl" scale="0.001 0.001 0.001"/>
    </geometry>
    <material name="silver"/>
  </visual>
  <collision>
    <origin xyz="0.16135 -0.320395 -0.344695" rpy="0 0 0"/>
    <geometry>
      <mesh filename="file:///home/lai/Desktop/ros2_ws/src/my_arm_description/meshes/servo_5_link_1.stl" scale="0.001 0.001 0.001"/>
    </geometry>
  </collision>
</link>

<link name="arm_5_link_1">
  <inertial>
    <origin xyz="0.027081086101920337 0.018331488424965195 -0.00038902637770105164" rpy="0 0 0"/>
    <mass value="0.2536556216496754"/>
    <inertia ixx="0.000132" iyy="0.000112" izz="0.000197" ixy="1.5e-05" iyz="-0.0" ixz="1e-06"/>
  </inertial>
  <visual>
    <origin xyz="-0.260792 0.020417 -0.309612" rpy="0 0 0"/>
    <geometry>
      <mesh filename="file:///home/lai/Desktop/ros2_ws/src/my_arm_description/meshes/arm_5_link_1.stl" scale="0.001 0.001 0.001"/>
    </geometry>
    <material name="silver"/>
  </visual>
  <collision>
    <origin xyz="-0.260792 0.020417 -0.309612" rpy="0 0 0"/>
    <geometry>
      <mesh filename="file:///home/lai/Desktop/ros2_ws/src/my_arm_description/meshes/arm_5_link_1.stl" scale="0.001 0.001 0.001"/>
    </geometry>
  </collision>
</link>

<link name="servo_6_link_1">
  <inertial>
    <origin xyz="0.33679400602412535 0.29104852781360147 0.014250617365778373" rpy="0 0 0"/>
    <mass value="0.2799142513209256"/>
    <inertia ixx="6.1e-05" iyy="3.8e-05" izz="7.1e-05" ixy="-2e-06" iyz="0.0" ixz="0.0"/>
  </inertial>
  <visual>
    <origin xyz="0.03322 0.304301 -0.295361" rpy="0 0 0"/>
    <geometry>
      <mesh filename="file:///home/lai/Desktop/ros2_ws/src/my_arm_description/meshes/servo_6_link_1.stl" scale="0.001 0.001 0.001"/>
    </geometry>
    <material name="silver"/>
  </visual>
  <collision>
    <origin xyz="0.03322 0.304301 -0.295361" rpy="0 0 0"/>
    <geometry>
      <mesh filename="file:///home/lai/Desktop/ros2_ws/src/my_arm_description/meshes/servo_6_link_1.stl" scale="0.001 0.001 0.001"/>
    </geometry>
  </collision>
</link>

<link name="lamp_link_1">
  <inertial>
    <origin xyz="0.04826812168887329 5.783412169857579e-07 -0.00018087533128824385" rpy="0 0 0"/>
    <mass value="0.42653519033217124"/>
    <inertia ixx="0.001163" iyy="0.001081" izz="0.001082" ixy="-0.0" iyz="-0.0" ixz="-3e-06"/>
  </inertial>
  <visual>
    <origin xyz="-0.321884 0.000251 -0.309612" rpy="0 0 0"/>
    <geometry>
      <mesh filename="file:///home/lai/Desktop/ros2_ws/src/my_arm_description/meshes/lamp_link_1.stl" scale="0.001 0.001 0.001"/>
    </geometry>
    <material name="silver"/>
  </visual>
  <collision>
    <origin xyz="-0.321884 0.000251 -0.309612" rpy="0 0 0"/>
    <geometry>
      <mesh filename="file:///home/lai/Desktop/ros2_ws/src/my_arm_description/meshes/lamp_link_1.stl" scale="0.001 0.001 0.001"/>
    </geometry>
  </collision>
</link>

<link name="servo_2_link_2">
  <inertial>
    <origin xyz="-0.21322000000851132 0.00037293502190464045 -0.031080972359841613" rpy="0 0 0"/>
    <mass value="0.2843033821982282"/>
    <inertia ixx="7.3e-05" iyy="6.2e-05" izz="4e-05" ixy="0.0" iyz="1e-06" ixz="-0.0"/>
  </inertial>
  <visual>
    <origin xyz="-0.21322 -0.00015 -0.16471" rpy="0 0 0"/>
    <geometry>
      <mesh filename="file:///home/lai/Desktop/ros2_ws/src/my_arm_description/meshes/servo_2_link_2.stl" scale="0.001 0.001 0.001"/>
    </geometry>
    <material name="silver"/>
  </visual>
  <collision>
    <origin xyz="-0.21322 -0.00015 -0.16471" rpy="0 0 0"/>
    <geometry>
      <mesh filename="file:///home/lai/Desktop/ros2_ws/src/my_arm_description/meshes/servo_2_link_2.stl" scale="0.001 0.001 0.001"/>
    </geometry>
  </collision>
</link>

<link name="arm_2_link_1">
  <inertial>
    <origin xyz="-0.0005037320295196879 -0.019702687953788513 0.09061320010830545" rpy="0 0 0"/>
    <mass value="0.8306265623311895"/>
    <inertia ixx="0.002713" iyy="0.002421" izz="0.000355" ixy="1e-06" iyz="1.7e-05" ixz="2.6e-05"/>
  </inertial>
  <visual>
    <origin xyz="0.0 -0.01895 -0.14643" rpy="0 0 0"/>
    <geometry>
      <mesh filename="file:///home/lai/Desktop/ros2_ws/src/my_arm_description/meshes/arm_2_link_1.stl" scale="0.001 0.001 0.001"/>
    </geometry>
    <material name="silver"/>
  </visual>
  <collision>
    <origin xyz="0.0 -0.01895 -0.14643" rpy="0 0 0"/>
    <geometry>
      <mesh filename="file:///home/lai/Desktop/ros2_ws/src/my_arm_description/meshes/arm_2_link_1.stl" scale="0.001 0.001 0.001"/>
    </geometry>
  </collision>
</link>

<joint name="l1" type="revolute">
  <origin xyz="-0.01251 -0.0001 0.17696" rpy="0 0 0"/>
  <parent link="base_link"/>
  <child link="arm_1_link_1"/>
  <axis xyz="-0.0 0.0 1.0"/>
  <limit upper="1.570796" lower="-1.570796" effort="100" velocity="100"/>
</joint>

<joint name="s3" type="fixed">
  <origin xyz="-0.0072 -0.01975 0.16217" rpy="0 0 0"/>
  <parent link="arm_2_link_1"/>
  <child link="servo_3_link_1"/>
</joint>

<joint name="l3" type="revolute">
  <origin xyz="0.0352 0.0183 0.0" rpy="0 0 0"/>
  <parent link="servo_3_link_1"/>
  <child link="arm_3_link_1"/>
  <axis xyz="0.0 -1.0 0.0"/>
  <limit upper="1.570796" lower="-1.570796" effort="100" velocity="100"/>
</joint>

<joint name="s4" type="fixed">
  <origin xyz="-0.1761 0.169292 -0.012234" rpy="0 0 0"/>
  <parent link="arm_3_link_1"/>
  <child link="servo_4_link_1"/>
</joint>

<joint name="l4" type="revolute">
  <origin xyz="0.354292 -0.188358 0.012434" rpy="0 0 0"/>
  <parent link="servo_4_link_1"/>
  <child link="arm_4_link_1"/>
  <axis xyz="1.0 0.0 0.0"/>
  <limit upper="1.570796" lower="-1.570796" effort="100" velocity="100"/>
</joint>

<joint name="s5" type="fixed">
  <origin xyz="-0.367542 0.321961 0.035895" rpy="0 0 0"/>
  <parent link="arm_4_link_1"/>
  <child link="servo_5_link_1"/>
</joint>

<joint name="l5" type="revolute">
  <origin xyz="0.422142 -0.340812 -0.035083" rpy="0 0 0"/>
  <parent link="servo_5_link_1"/>
  <child link="arm_5_link_1"/>
  <axis xyz="0.0 1.0 0.0"/>
  <limit upper="1.570796" lower="-1.570796" effort="100" velocity="100"/>
</joint>

<joint name="s6" type="fixed">
  <origin xyz="-0.294012 -0.283884 -0.014251" rpy="0 0 0"/>
  <parent link="arm_5_link_1"/>
  <child link="servo_6_link_1"/>
</joint>

<joint name="l6" type="revolute">
  <origin xyz="0.355104 0.30405 0.014251" rpy="0 0 0"/>
  <parent link="servo_6_link_1"/>
  <child link="lamp_link_1"/>
  <axis xyz="1.0 0.0 0.0"/>
  <limit upper="1.570796" lower="-1.570796" effort="100" velocity="100"/>
</joint>

<joint name="s1" type="fixed">
  <origin xyz="0.22573 0.00025 -0.01225" rpy="0 0 0"/>
  <parent link="arm_1_link_1"/>
  <child link="servo_2_link_2"/>
</joint>

<joint name="l2" type="revolute">
  <origin xyz="-0.21322 0.0188 -0.01828" rpy="0 0 0"/>
  <parent link="servo_2_link_2"/>
  <child link="arm_2_link_1"/>
  <axis xyz="0.0 -1.0 0.0"/>
  <limit upper="1.570796" lower="-1.570796" effort="100" velocity="100"/>
</joint>

</robot>
